Workbook

Sheet paleosols
K1: Data Sources | P1: Contextual Information | AG1: Measured Values | BY1: Derived Values | DU1: Other Measurements/Observations | EW1: CO2 estimates
B2: These columns will auto-populate from information you provided in the first tab | E2: These columns contain formulas that will autocalculate based on entires in other parts of the workbook | K2: These columns will auto-populate from information you provided in the first tab | N2: If data from other publications were used to generate a paleoCO2 estimate, list those other publications here | Q2: ame of formation and member from which paleosol samples were collected. If both are available, use format: formation, member. If only the formation name is available, type the formation name. Otherwise enter NA | T2: Select from pull-down menu | U2: if other selected in previous column, enter here the name of the other geodetic datum used | X2: If CO2 estimates reported in the study come from more than one section (sedimentary sequence), this column should be used to disambigute sections. This is especially useful for comparing age data (on age data tab) with the stratigraphic levels entered in the subsequent column of this tab | Y2: height above or depth below recognizable boundary or interval. Organize data from youngest at the top to oldest at the bottom | Z2: Age of paleosol in millions of years. If age was reported as a range, enter the midpoint of the range here, use the endpoints of range to calculate the length of error bars and enter 'uniform distribution across range' under 'type of uncertainty' | AA2: length of error bar extending to older ages | AB2: length of error bar extending to younger ages | AD2: list here any details that might help users of the database understand the development of the age-depth model for this study. Enter data used to generate the age-depth model on the age data tab. | AE2: If the soil is best characterised as having formed during a single, discrete pedogenic event enter Yes. If the soil is best charactised as having formed continously as sediment accumulated and/or during more than one pedogenic event, enter No. | AF2: This column is to help organize data that should be considered together as part of the same soil, e.g., for consideration of paleo soil profiles. Enter the same number for each row that is part of a soil formed during a discrete pedogenic event. Enter 'NA' for composite soils unless you want to link analyses at different depths. | AG2: Mean of replicate measurements of the d13C values (‰ PDB) of samples from different locations within individual pedogenic calcium carbonate nodules/coatings/filaments, etc. Replicates should be analyses of different samples of the same material (e.g., different locations drilled on the same nodule) but should not be different aliquots of the same powder because analytical error tends to be small than natural variability. Analyses of different nodules (or other carbonate morphotypes) should be reported on different rows even if they are from the same stratigraphic level. | AH2: 2 standard deviations of replicate d13Ccc measurements | AI2: number of replicate d13Ccc measurements | AJ2: if d13Ccc values were taken from literature, provide reference here | AK2: Mean of replicate measurements of the d13C values (‰ PDB) of organic carbon occluded in paleosol carbonates. Replicates should be the same as those for carbonate nodule carbonate d13C analysis. | AL2: 2 standard deviations of replicate d13Com measurements | AM2: number of replicate d13Coccluded om measurements | AN2: Mean of replicate measurements of the d13C values (‰ PDB) of bulk paleosols organic carbon. Replicates should be discrete bulk samples (e.g., collected in different bags) from the same stratigraphic level. | AO2: 2 standard deviations of replicate d13Cbulk om measurements | AP2: number of replicate d13Cbulk om measurements | AQ2: if d13Com values were taken from literature, provide reference here | AR2: Mean of replicate measurements of the d13C values (‰ PDB) of tooth enamel. Replicates should be different samples from the same tooth. Analyses of different teeth should be reported on different rows | AS2: 2 standard deviations of replicate d13Cenamel measurements | AT2: number of replicate d13Cenamel measurements | AU2: if d13Cenamel values were taken from literature, provide reference here | AV2: Mean of replicate measurements of the d18O values (‰ PDB) of samples from different locations within individual pedogenic calcium carbonate nodules/coatings/filaments, etc. Replicates should be the same as those for carbonate nodule carbonate d13C analysis. | AW2: 2 standard deviations of replicate d18Occ measurements | AX2: number of replicate d18Occ measurements | AY2: if d18Occ values were taken from literature, provide reference here | AZ2: Vertical distance from the paleosurface (if preserved and recognizable) to the top of the Bk horizon | BA2: Thickness of overburden for calculation of compaction | BX2: number of replicate geochemical analyses | BY2: estimate of the d13C value (‰ PDB) of CO2 that was respired in the paleosol | BZ2: Select from pull-down menu | CA2: if other selected in previous column, enter here the name of other method for assigning d13Cr | CB2: references for method used to determine d13Cr and, if applicable, reference for the data used to determine d13Cr or the reference in which the d13Cr values were reported | CC2: 2 standard deviations around mean d13Cr value including error in any transfer functions used | CD2: what measurement, transfer function, natural variability or other error errors were considered when assigning a value for the uncertainty | CE2: if 2 sigma uncertainty is not available, enter other uncertainty here | CG2: estimate of the d13C value (‰ PDB) of atmospheric CO2 | CH2: Select from pull-down menu | CI2: if other selected in previous column, enter here the name of other method for assigning d13Ca | CJ2: references for method used to determine d13Ca and, if applicable, reference for the data used to determine d13Ca or the reference in which the d13Ca values were reported | CK2: 2 standard deviations around mean d13Ca value including error in any transfer functions used | CL2: what measurement, transfer function, natural variability or other error errors were considered when assigning a value for the uncertainty | CM2: if 2 sigma uncertainty is not available, enter other uncertainty here | CO2: Best estimate of the temperature of paleosol carbonate formation. For clumped isotope temperatures, enter apparent temperature calculated from clumped DX value | CP2: Select from pull-down menu | CQ2: if other selected in previous column, enter here the name of the other temperature approach | CR2: include here the reference for calibration of thermometer and, if applicable, the reference for the calculation of calcium carbonate formation temperature from other (e.g., mean annual) temperature. For clumped isotope temperatures enter NA and fill in clumped isotope-specific columns to the right. If temperature was reported in a different study include there the reference in which the temperature was reported. | CS2: 2 standard deviations around mean temperature including error in any transfer functions used | CT2: what measurement, transfer function, natural variability or other error errors were considered when assigning a value for the uncertainty | CU2: if 2 sigma uncertainty is not available, enter other uncertainty here | CW2: Number of replicates. For clumped isotope data, replicates are individual acid digestions and analyses of different aliquots of the same sample powder. If multiple locations on a single nodule were analyzed for clumped isotope compositions, enter data from each location on its own row and make a note in the last column. | CX2: Select from pull-down menu | CY2: if other selected in previous column, enter here the name of other clumped isotope standardization (e.g., thermometers and standardizations for dual-clumped thermometry, other clumped isotope thermometers, or other community standards) | CZ2: For clumped isotope data, enter Earthchem database doi for link to full clumped isotope dataset | DA2: estimate of the d13C value (‰ PDB) of soil CO2 | DB2: references for calcite-CO2 carbon isotope fractionation factor used | DC2: 2 standard deviations around mean d13Cs value including error in any transfer functions used | DD2: calculated from depth of overburden and measured depth to Bk horizon | DE2: estimate of mean annual precipitation during soil formation | DF2: Select from pull-down menu | DG2: if other selected in previous column, enter here the name of the other approach for estimating mean annual precipitation | DH2: 2 standard deviations around MAP estimate including error in any transfer functions used | DI2: what measurement, transfer function, natural variability or other error errors were considered when assigning a value for the uncertainty | DJ2: if 2 sigma uncertainty is not available, enter other uncertainty here | DK2: if 2 sigma uncertainty is not available, enter type of other uncertainty here | DL2: include here references for calibration of the approach used and, if applicable, the reference for the data used to determine MAP or the reference in which the value of MAP was reported | DM2: estimate of soil respired CO2 concentration (Soil CO2 – atmospheric CO2) at the uncompacted depth below paleosurface. If S(z) was reported as a range, enter the midpoint of the range here, use the endpoints of range to calculate the length of error bars and enter 'uniform distribution across range' under 'type of uncertainty' | DN2: Select from pull-down menu | DO2: if other selected in previous column, enter here the name of the other approach for estimating S | DP2: S(z) uncertainty can be skewed. Enter here the length of the upper error bar | DQ2: S(z) uncertainty can be skewed. Enter here the length of the lower error bar | DR2: what measurement, transfer function, natural variability or other error errors were considered when assigning a value for the uncertainty | DT2: include here references for calibration of the approach used and, if applicable, the reference for the data used to determine S or the reference in which the value of S was reported | DU2: interpreted soil order | DV2: Select from pull-down menu | DW2: if other selected in previous column, enter here the name of the other taxonomic system | DX2: what features of the paleosol were used to assign a soil order | DY2: total depth of soil (measured, i.e. not uncompacted) if measured | DZ2: Select from pull-down menu | EA2: Select from pull-down menu | EB2: if other selected in previous column, enter here the name of the other carbonate type | EC2: Depth below top of horizon in which calcium carbonate was collected (measured, i.e. not uncompacted, but corrected for slope of exposure/dip of bedding) | ED2: Was sample drilled to avoid sparry calcite: yes/no | EE2: Select from pull-down menu | EF2: if other selected in previous column, enter name of other petrographic analysis here | EI2: Select from pull-down menu | EJ2: if other selected in previous column, or if more than one carbomate mineral is present, enter name of other carbonate mineral(s) here | EK2: Soil horizon from which organic matter samples were collected | EL2: Depth below top of horizon in which organic matter was collected (measured, i.e. not uncompacted, but corrected for slope of exposure/dip of bedding) | EM2: Select from pull-down menu | EN2: if other selected in previous column, enter name of other organic matter type here | EO2: Select from pull-down menu | EP2: if other selected in previous column, enter here a description of the other method used to remove carbonate | EQ2: if bulk geochemistry was measured, what elements were measured? | ES2: Select from pull-down menu | ET2: if other selected in previous column, enter name of other dissolution method here | EU2: Select from pull-down menu | EV2: if other selected in previous column, enter name of other analysis method here | EW2: If CO2 was reported as a range, enter the midpoint of the range here, use the endpoints of range to calculate the length of error bars and enter 'uniform distribution across range' under 'type of uncertainty' | EY2: length of error bar extending to higher CO2 | EZ2: length of error bar extending to lower CO2 | FD2: value of 97.5 percentile | FE2: value of 2.5 percentile
A3: proxy | B3: first_author_last_name | C3: publication_year | D3: doi | E3: age_ka | F3: Age_uncertainty_pos_ka (length of error bar extending to older ages) | G3: Age_uncertainty_neg_ka (length of error bar extending to younger ages) | H3: CO2_ppm | I3: CO2_uncertainty_pos_ppm (length of error bar extending to higher CO2) | J3: CO2_uncertainty_neg_ppm (length of error bar extending to lower CO2) | K3: name of individual entering data | L3: contact email of individual entering data | M3: Reference of the data product | N3: Additional publications that are part of the dataset | O3: Explanation for how each additional publication links to the dataset | P3: Sample ID | Q3: Rock formation name | R3: Modern Latitude (decimal degree, south negative) | S3: Modern Longitude (decimal degree, west negative) | T3: geodetic datum | U3: other geodetic datum | V3: Paleo Latitude (decimal degree, south negative) | W3: Paleo Longitude (decimal degree, west negative) | X3: section number | Y3: Stratigraphic level (m) | Z3: Age (Ma) | AA3: Age uncertainty positive (Ma) | AB3: Age uncertainty negative (Ma) | AC3: type of uncertainty on age (e.g. 2sd, 2se, 97.5/2.5 percentile) | AD3: notes on age determination | AE3: Discrete pedogenic event? Yes/No | AF3: paleosol number | AG3: d13Ccc (‰ PDB) | AH3: d13Ccc uncertainty ±2s (‰ PDB) | AI3: n d13Ccc | AJ3: Reference for d13Ccc | AK3: d13Coccluded om (‰ PDB) | AL3: d13Coccluded om uncertainty ±2s (‰ PDB) | AM3: n d13Coccluded om | AN3: d13Cbulk paleosol om (‰ PDB) | AO3: d13Cbulk paleosol om uncertainty ±2s (‰ PDB) | AP3: n d13Cbulk paleosol om | AQ3: Reference for d13Com | AR3: d13Cenamel (‰ PDB) | AS3: d13Cenamel uncertainty ±2s (‰ PDB) | AT3: n d13Cenamel | AU3: Reference for d13Cenamel | AV3: d18Occ (‰ PDB) | AW3: d18Occ uncertainty ±2s (‰ PDB) | AX3: n d18Occ | AY3: Reference for d18Occ | AZ3: Depth to carbonate horizon (cm) | BA3: Burial Depth (m) | BB3: SiO2 wt% | BC3: SiO2 uncertainty ± 2s stdev (wt%) | BD3: TiO2 wt% | BE3: TiO2 uncertainty ± 2s stdev (wt%) | BF3: Al2O3 wt% | BG3: Al2O3 uncertainty ± 2s stdev (wt%) | BH3: Fe2O3 wt% | BI3: Fe2O3 uncertainty ± 2s stdev (wt%) | BJ3: MnO wt% | BK3: MnO uncertainty ± 2s stdev (wt%) | BL3: MgO wt% | BM3: MgO uncertainty ± 2s stdev (wt%) | BN3: CaO wt% | BO3: CaO uncertainty ± 2s stdev (wt%) | BP3: Na2O wt% | BQ3: Na2O uncertainty ± 2s stdev (wt%) | BR3: K2O wt% | BS3: K2O uncertainty ± 2s stdev (wt%) | BT3: P2O5 wt% | BU3: P2O5 uncertainty ± 2s stdev (wt%) | BV3: ZrO2 wt% | BW3: ZrO2 uncertainty ± 2s stdev (wt%) | BX3: n geochemical analyses | BY3: d13Cr (‰ PDB) | BZ3: d13Cr approach | CA3: other d13Cr approach | CB3: d13Cr reference(s) | CC3: d13Cr uncertainty ±2s (‰ PDB) | CD3: which factors constitute the uncertainty? | CE3: other d13Cr uncertainty (‰ PDB) | CF3: type of other uncertainty (e.g. 2se, 97.5/2.5 percentile) | CG3: d13Ca (‰ PDB) | CH3: d13Ca approach | CI3: other d13Ca approach | CJ3: d13Ca reference(s) | CK3: d13Ca uncertainty ±2s (‰ PDB) | CL3: which factors constitute the uncertainty? | CM3: other d13Ca uncertainty (‰ PDB) | CN3: type of other uncertainty (e.g. 2se, 97.5/2.5 percentile) | CO3: Temperature of calcium carbonate formation (°C) | CP3: Temperature estimation approach | CQ3: other temperature estimation approach | CR3: Reference(s) for temperature estimation approach | CS3: Temperature uncertainty ±2s (°C) | CT3: which factors constitute the uncertainty? | CU3: other temperature uncertainty (°C) | CV3: type of other uncertainty (e.g. 2se, 97.5/2.5 percentile) | CW3: n clumped isotope temperature replicates | CX3: clumped isotope thermometer standardization | CY3: other clumped isotope thermometer standardization | CZ3: EarthChem ClumpsDB doi (https://earthchem.org/communities/clumpdb/ [earthchem.org]) | DA3: d13Cs (‰ PDB) | DB3: d13Cs reference(s) | DC3: d13Cs uncertainty ±2s (‰ PDB) | DD3: Uncompacted depth to carbonate horizon (cm) | DE3: Mean Annual Precipitation (MAP) (mm) | DF3: MAP approach | DG3: other MAP approach | DH3: MAP uncertainty ±2s (mm) | DI3: which factors constitute the uncertainty? | DJ3: other MAP uncertainty (mm) | DK3: type of other uncertainty (e.g. 2se, 97.5/2.5 percentile) | DL3: MAP reference(s) | DM3: Component of soil pore space CO2 from respiration, i.e. S(z) ppm | DN3: S(z) approach | DO3: other S(z) approach | DP3: S(z) uncertainty pos ppm | DQ3: S(z) uncertainty neg ppm | DR3: which factors constitute the uncertainty? | DS3: type of uncertainty (e.g. 2sd, 2se, 97.5/2.5 percentile) | DT3: S(z) reference(s) | DU3: Soil order | DV3: taxonomic system for soil order designation | DW3: other taxonomic system | DX3: Defining features for soil order designation | DY3: Soil depth (cm) | DZ3: Soil texture (Grain size) | EA3: Carbonate type | EB3: other carbonate type | EC3: Depth of carbonte sample in horizon (cm) | ED3: Calcite spar (large crystals) avoided? Yes/No | EE3: Petrographic analysis of thin sections? TL=transmitted light, CL=cathodoluminescence | EF3: other petrographic analysis | EG3: SEM analysis of thin sections? Yes/No | EH3: clumped isotope analysis? Yes/No | EI3: Mineralogy of carbonates? | EJ3: other mineraology of carbonates | EK3: Soil horizon for organic matter A, B, C, etc. | EL3: Depth of om sample in soil horizon | EM3: Organic matter type | EN3: other organic matter type | EO3: Method of removal of calcium carbonate prior to om analysis | EP3: other method of removal of calcium carbonate | EQ3: Bulk geochem type | ER3: horizon for bulk geochemsitry | ES3: dissolution method for bulk geochemistry | ET3: other dissolution method | EU3: analysis method for bulk geochemistry | EV3: other analysis method for bulk geochemistry | EW3: Atmospheric CO2 mean ppmV | EX3: Atmospheric CO2 median ppmV | EY3: Atmospheric CO2 uncertainty pos ppmV | EZ3: Atmospheric CO2 uncertainty neg ppmV | FA3: variables considered in error propagation | FB3: error propagation method | FC3: type of uncertainty on CO2 (e.g. 2sd, 2se, 97.5/2.5 percentile) | FD3: Atmospheric CO2_97.5 percentile ppmV | FE3: Atmospheric CO2_2.5 percentile ppmV | FF3: Notes
A4: paleosol | B4: ='Start here when entering data'!$D$11 -> Ghosh | C4: ='Start here when entering data'!$D$12 -> 2005 | D4: ='Start here when entering data'!$D$13 -> 10.1007/0-387-27048-5_2 | E4: =IF( Z4="NA","NA",Z4*1000) -> 275000 | F4: =IF( AA4="NA","NA",AA4*1000) -> 15000 | G4: =IF( AB4="NA","NA",AB4*1000) -> 15000 | H4: =IF(EX4="NA",EW4,EX4) -> 715 | I4: =IF( EY4="NA","NA",EY4) -> 175 | J4: =IF( EZ4="NA","NA",EZ4) -> 175 | K4: ='Start here when entering data'!$D$8 -> Jiawei Da | L4: ='Start here when entering data'!$D$9 -> jiawei@utexas.edu | M4: ='Start here when entering data'!$D$14 -> Ghosh P, Bhattacharya S K, Ghosh P. Atmospheric CO2 during the Late Paleozoic and Mesozoic: estimates from Indian soils[M]//A history of atmospheric CO2 and its effects on plants, animals, and ecosystems. New York, NY: Springer New York, 2005: 8-34. | N4: Ghosh P, Ghosh P, Bhattacharya S K. CO2 levels in the Late Palaeozoic and Mesozoic atmosphere from soil carbonate and organic matter, Satpura basin, Central India[J]. Palaeogeography, palaeoclimatology, palaeoecology, 2001, 170(3-4): 219-236. | O4: Ghosh et al (2001) provided the isotope data for Motur, Denwa, and Bagra formation. | P4: NA | Q4: Motur | R4: 22.2 | S4: 78.68 | T4: NA | U4: NA | V4: NA | W4: NA | X4: NA | Y4: NA | Z4: 275 | AA4: 15 | AB4: 15 | AC4: NA | AD4: NA | AE4: NA | AF4: NA | AG4: -6.5 | AH4: 1.6 | AI4: 21 | AJ4: Ghosh P, Ghosh P, Bhattacharya S K. CO2 levels in the Late Palaeozoic and Mesozoic atmosphere from soil carbonate and organic matter, Satpura basin, Central India[J]. Palaeogeography, palaeoclimatology, palaeoecology, 2001, 170(3-4): 219-236. | AK4: -23.5 | AL4: 1 | AM4: 8 | AN4: NA | AO4: NA | AP4: NA | AQ4: Ghosh P, Ghosh P, Bhattacharya S K. CO2 levels in the Late Palaeozoic and Mesozoic atmosphere from soil carbonate and organic matter, Satpura basin, Central India[J]. Palaeogeography, palaeoclimatology, palaeoecology, 2001, 170(3-4): 219-236. | AR4: NA | AS4: NA | AT4: NA | AU4: NA | AV4: -12.3 | AW4: 1.8 | AX4: 21 | AY4: Ghosh P, Ghosh P, Bhattacharya S K. CO2 levels in the Late Palaeozoic and Mesozoic atmosphere from soil carbonate and organic matter, Satpura basin, Central India[J]. Palaeogeography, palaeoclimatology, palaeoecology, 2001, 170(3-4): 219-236. | AZ4: NA | BA4: NA | BB4: NA | BC4: NA | BD4: NA | BE4: NA | BF4: NA | BG4: NA | BH4: NA | BI4: NA | BJ4: NA | BK4: NA | BL4: NA | BM4: NA | BN4: NA | BO4: NA | BP4: NA | BQ4: NA | BR4: NA | BS4: NA | BT4: NA | BU4: NA | BV4: NA | BW4: NA | BX4: NA | BY4: -23.5 | BZ4: equal to d13C value of bulk paleosol organic matter | CA4: NA | CB4: NA | CC4: NA | CD4: NA | CE4: NA | CF4: NA | CG4: -2.5 | CH4: other | CI4: assuming 21‰ fractionation between d13Ca and d13Corg | CJ4: Mora et al., 1992 | CK4: NA | CL4: NA | CM4: NA | CN4: NA | CO4: 20 | CP4: other | CQ4: paleolatitude, maximum monthly temperature | CR4: Ekart et al., 1995 | CS4: NA | CT4: NA | CU4: NA | CV4: NA | CW4: NA | CX4: NA | CY4: NA | CZ4: NA | DA4: NA | DB4: NA | DC4: NA | DD4: NA | DE4: NA | DF4: NA | DG4: NA | DH4: NA | DI4: NA | DJ4: NA | DK4: NA | DL4: NA | DM4: 3000-5000 | DN4: NA | DO4: NA | DP4: NA | DQ4: NA | DR4: NA | DS4: NA | DT4: NA | DU4: aridisol | DV4: USDA | DW4: NA | DX4: NA | DY4: NA | DZ4: sand | EA4: nodules | EB4: NA | EC4: >25 | ED4: NA | EE4: NA | EF4: NA | EG4: NA | EH4: NA | EI4: NA | EJ4: NA | EK4: B | EL4: NA | EM4: NA | EN4: NA | EO4: NA | EP4: NA | EQ4: NA | ER4: NA | ES4: NA | ET4: NA | EU4: NA | EV4: NA | EW4: 715 | EX4: NA | EY4: 175 | EZ4: 175 | FA4: S(z) | FB4: NA | FC4: NA | FD4: NA | FE4: NA | FF4: NA
A5: paleosol | B5: ='Start here when entering data'!$D$11 -> Ghosh | C5: ='Start here when entering data'!$D$12 -> 2005 | D5: ='Start here when entering data'!$D$13 -> 10.1007/0-387-27048-5_2 | E5: =IF( Z5="NA","NA",Z5*1000) -> 235000 | F5: =IF( AA5="NA","NA",AA5*1000) -> 5000 | G5: =IF( AB5="NA","NA",AB5*1000) -> 5000 | H5: =IF(EX5="NA",EW5,EX5) -> 1210 | I5: =IF( EY5="NA","NA",EY5) -> 300 | J5: =IF( EZ5="NA","NA",EZ5) -> 300 | K5: ='Start here when entering data'!$D$8 -> Jiawei Da | L5: ='Start here when entering data'!$D$9 -> jiawei@utexas.edu | M5: ='Start here when entering data'!$D$14 -> Ghosh P, Bhattacharya S K, Ghosh P. Atmospheric CO2 during the Late Paleozoic and Mesozoic: estimates from Indian soils[M]//A history of atmospheric CO2 and its effects on plants, animals, and ecosystems. New York, NY: Springer New York, 2005: 8-34. | N5: Ghosh P, Ghosh P, Bhattacharya S K. CO2 levels in the Late Palaeozoic and Mesozoic atmosphere from soil carbonate and organic matter, Satpura basin, Central India[J]. Palaeogeography, palaeoclimatology, palaeoecology, 2001, 170(3-4): 219-236. | O5: Ghosh et al (2001) provided the isotope data for Motur, Denwa, and Bagra formation. | P5: NA | Q5: Denwa | R5: 22.6 | S5: 78.1 | T5: NA | U5: NA | V5: NA | W5: NA | X5: NA | Y5: NA | Z5: 235 | AA5: 5 | AB5: 5 | AC5: NA | AD5: NA | AE5: NA | AF5: NA | AG5: -6.7 | AH5: 1 | AI5: 19 | AJ5: Ghosh P, Ghosh P, Bhattacharya S K. CO2 levels in the Late Palaeozoic and Mesozoic atmosphere from soil carbonate and organic matter, Satpura basin, Central India[J]. Palaeogeography, palaeoclimatology, palaeoecology, 2001, 170(3-4): 219-236. | AK5: -24.6 | AL5: 1 | AM5: 6 | AN5: NA | AO5: NA | AP5: NA | AQ5: Ghosh P, Ghosh P, Bhattacharya S K. CO2 levels in the Late Palaeozoic and Mesozoic atmosphere from soil carbonate and organic matter, Satpura basin, Central India[J]. Palaeogeography, palaeoclimatology, palaeoecology, 2001, 170(3-4): 219-236. | AR5: NA | AS5: NA | AT5: NA | AU5: NA | AV5: -6.5 | AW5: 1.4 | AX5: 19 | AY5: Ghosh P, Ghosh P, Bhattacharya S K. CO2 levels in the Late Palaeozoic and Mesozoic atmosphere from soil carbonate and organic matter, Satpura basin, Central India[J]. Palaeogeography, palaeoclimatology, palaeoecology, 2001, 170(3-4): 219-236. | AZ5: NA | BA5: NA | BB5: NA | BC5: NA | BD5: NA | BE5: NA | BF5: NA | BG5: NA | BH5: NA | BI5: NA | BJ5: NA | BK5: NA | BL5: NA | BM5: NA | BN5: NA | BO5: NA | BP5: NA | BQ5: NA | BR5: NA | BS5: NA | BT5: NA | BU5: NA | BV5: NA | BW5: NA | BX5: NA | BY5: -24.6 | BZ5: equal to d13C value of bulk paleosol organic matter | CA5: NA | CB5: NA | CC5: NA | CD5: NA | CE5: NA | CF5: NA | CG5: -3.6 | CH5: other | CI5: assuming 21‰ fractionation between d13Ca and d13Corg | CJ5: Mora et al., 1993 | CK5: NA | CL5: NA | CM5: NA | CN5: NA | CO5: 25 | CP5: other | CQ5: paleolatitude, maximum monthly temperature | CR5: Ekart et al., 1996 | CS5: NA | CT5: NA | CU5: NA | CV5: NA | CW5: NA | CX5: NA | CY5: NA | CZ5: NA | DA5: NA | DB5: NA | DC5: NA | DD5: NA | DE5: NA | DF5: NA | DG5: NA | DH5: NA | DI5: NA | DJ5: NA | DK5: NA | DL5: NA | DM5: 3000-5000 | DN5: NA | DO5: NA | DP5: NA | DQ5: NA | DR5: NA | DS5: NA | DT5: NA | DU5: aridisol | DV5: USDA | DW5: NA | DX5: NA | DY5: NA | DZ5: sand | EA5: nodules | EB5: NA | EC5: >25 | ED5: NA | EE5: NA | EF5: NA | EG5: NA | EH5: NA | EI5: NA | EJ5: NA | EK5: B | EL5: NA | EM5: NA | EN5: NA | EO5: NA | EP5: NA | EQ5: NA | ER5: NA | ES5: NA | ET5: NA | EU5: NA | EV5: NA | EW5: 1210 | EX5: NA | EY5: 300 | EZ5: 300 | FA5: S(z) | FB5: NA | FC5: NA | FD5: NA | FE5: NA | FF5: NA
A6: paleosol | B6: ='Start here when entering data'!$D$11 -> Ghosh | C6: ='Start here when entering data'!$D$12 -> 2005 | D6: ='Start here when entering data'!$D$13 -> 10.1007/0-387-27048-5_2 | E6: =IF( Z6="NA","NA",Z6*1000) -> 225000 | F6: =IF( AA6="NA","NA",AA6*1000) -> 15000 | G6: =IF( AB6="NA","NA",AB6*1000) -> 15000 | H6: =IF(EX6="NA",EW6,EX6) -> 1170 | I6: =IF( EY6="NA","NA",EY6) -> 290 | J6: =IF( EZ6="NA","NA",EZ6) -> 290 | K6: ='Start here when entering data'!$D$8 -> Jiawei Da | L6: ='Start here when entering data'!$D$9 -> jiawei@utexas.edu | M6: ='Start here when entering data'!$D$14 -> Ghosh P, Bhattacharya S K, Ghosh P. Atmospheric CO2 during the Late Paleozoic and Mesozoic: estimates from Indian soils[M]//A history of atmospheric CO2 and its effects on plants, animals, and ecosystems. New York, NY: Springer New York, 2005: 8-34. | O6: NA | P6: NA | Q6: Tiki | R6: NA | S6: NA | T6: NA | U6: NA | V6: NA | W6: NA | X6: NA | Y6: NA | Z6: 225 | AA6: 15 | AB6: 15 | AC6: NA | AD6: NA | AE6: NA | AF6: NA | AG6: -6.9 | AH6: 1.6 | AI6: 11 | AJ6: Ghosh P, Bhattacharya S K, Ghosh P. Atmospheric CO2 during the Late Paleozoic and Mesozoic: estimates from Indian soils[M]//A history of atmospheric CO2 and its effects on plants, animals, and ecosystems. New York, NY: Springer New York, 2005: 8-34. | AK6: -24.7 | AL6: 1.2 | AM6: 7 | AN6: NA | AO6: NA | AP6: NA | AQ6: Ghosh P, Bhattacharya S K, Ghosh P. Atmospheric CO2 during the Late Paleozoic and Mesozoic: estimates from Indian soils[M]//A history of atmospheric CO2 and its effects on plants, animals, and ecosystems. New York, NY: Springer New York, 2005: 8-34. | AR6: NA | AS6: NA | AT6: NA | AU6: NA | AV6: -4.7 | AW6: 2 | AX6: 11 | AY6: Ghosh P, Bhattacharya S K, Ghosh P. Atmospheric CO2 during the Late Paleozoic and Mesozoic: estimates from Indian soils[M]//A history of atmospheric CO2 and its effects on plants, animals, and ecosystems. New York, NY: Springer New York, 2005: 8-34. | AZ6: NA | BA6: NA | BB6: NA | BC6: NA | BD6: NA | BE6: NA | BF6: NA | BG6: NA | BH6: NA | BI6: NA | BJ6: NA | BK6: NA | BL6: NA | BM6: NA | BN6: NA | BO6: NA | BP6: NA | BQ6: NA | BR6: NA | BS6: NA | BT6: NA | BU6: NA | BV6: NA | BW6: NA | BX6: NA | BY6: -24.7 | BZ6: equal to d13C value of bulk paleosol organic matter | CA6: NA | CB6: NA | CC6: NA | CD6: NA | CE6: NA | CF6: NA | CG6: -3.7 | CH6: other | CI6: assuming 21‰ fractionation between d13Ca and d13Corg | CJ6: Mora et al., 1994 | CK6: NA | CL6: NA | CM6: NA | CN6: NA | CO6: 25 | CP6: other | CQ6: paleolatitude, maximum monthly temperature | CR6: Ekart et al., 1997 | CS6: NA | CT6: NA | CU6: NA | CV6: NA | CW6: NA | CX6: NA | CY6: NA | CZ6: NA | DA6: NA | DB6: NA | DC6: NA | DD6: NA | DE6: NA | DF6: NA | DG6: NA | DH6: NA | DI6: NA | DJ6: NA | DK6: NA | DL6: NA | DM6: 3000-5000 | DN6: NA | DO6: NA | DP6: NA | DQ6: NA | DR6: NA | DS6: NA | DT6: NA | DU6: aridisol | DV6: USDA | DW6: NA | DX6: NA | DY6: NA | DZ6: sand | EA6: nodules | EB6: NA | EC6: >25 | ED6: NA | EE6: NA | EF6: NA | EG6: NA | EH6: NA | EI6: NA | EJ6: NA | EK6: B | EL6: NA | EM6: NA | EN6: NA | EO6: NA | EP6: NA | EQ6: NA | ER6: NA | ES6: NA | ET6: NA | EU6: NA | EV6: NA | EW6: 1170 | EX6: NA | EY6: 290 | EZ6: 290 | FA6: S(z) | FB6: NA | FC6: NA | FD6: NA | FE6: NA | FF6: NA
A7: paleosol | B7: ='Start here when entering data'!$D$11 -> Ghosh | C7: ='Start here when entering data'!$D$12 -> 2005 | D7: ='Start here when entering data'!$D$13 -> 10.1007/0-387-27048-5_2 | E7: =IF( Z7="NA","NA",Z7*1000) -> 175000 | F7: =IF( AA7="NA","NA",AA7*1000) -> 30000 | G7: =IF( AB7="NA","NA",AB7*1000) -> 30000 | H7: =IF(EX7="NA",EW7,EX7) -> 2225 | I7: =IF( EY7="NA","NA",EY7) -> 550 | J7: =IF( EZ7="NA","NA",EZ7) -> 550 | K7: ='Start here when entering data'!$D$8 -> Jiawei Da | L7: ='Start here when entering data'!$D$9 -> jiawei@utexas.edu | M7: ='Start here when entering data'!$D$14 -> Ghosh P, Bhattacharya S K, Ghosh P. Atmospheric CO2 during the Late Paleozoic and Mesozoic: estimates from Indian soils[M]//A history of atmospheric CO2 and its effects on plants, animals, and ecosystems. New York, NY: Springer New York, 2005: 8-34. | N7: Ghosh P, Ghosh P, Bhattacharya S K. CO2 levels in the Late Palaeozoic and Mesozoic atmosphere from soil carbonate and organic matter, Satpura basin, Central India[J]. Palaeogeography, palaeoclimatology, palaeoecology, 2001, 170(3-4): 219-236. | O7: Ghosh et al (2001) provided the isotope data for Motur, Denwa, and Bagra formation. | P7: NA | Q7: Bagra | R7: 22.63 | S7: 78.4 | T7: NA | U7: NA | V7: NA | W7: NA | X7: NA | Y7: NA | Z7: 175 | AA7: 30 | AB7: 30 | AC7: NA | AD7: NA | AE7: NA | AF7: NA | AG7: -6.1 | AH7: 1.6 | AI7: 29 | AJ7: Ghosh P, Ghosh P, Bhattacharya S K. CO2 levels in the Late Palaeozoic and Mesozoic atmosphere from soil carbonate and organic matter, Satpura basin, Central India[J]. Palaeogeography, palaeoclimatology, palaeoecology, 2001, 170(3-4): 219-236. | AK7: -26.1 | AL7: 2.4 | AM7: 6 | AN7: NA | AO7: NA | AP7: NA | AQ7: Ghosh P, Ghosh P, Bhattacharya S K. CO2 levels in the Late Palaeozoic and Mesozoic atmosphere from soil carbonate and organic matter, Satpura basin, Central India[J]. Palaeogeography, palaeoclimatology, palaeoecology, 2001, 170(3-4): 219-236. | AR7: NA | AS7: NA | AT7: NA | AU7: NA | AV7: -6.6 | AW7: 1.6 | AX7: 29 | AY7: Ghosh P, Ghosh P, Bhattacharya S K. CO2 levels in the Late Palaeozoic and Mesozoic atmosphere from soil carbonate and organic matter, Satpura basin, Central India[J]. Palaeogeography, palaeoclimatology, palaeoecology, 2001, 170(3-4): 219-236. | AZ7: NA | BA7: NA | BB7: NA | BC7: NA | BD7: NA | BE7: NA | BF7: NA | BG7: NA | BH7: NA | BI7: NA | BJ7: NA | BK7: NA | BL7: NA | BM7: NA | BN7: NA | BO7: NA | BP7: NA | BQ7: NA | BR7: NA | BS7: NA | BT7: NA | BU7: NA | BV7: NA | BW7: NA | BX7: NA | BY7: -26.1 | BZ7: equal to d13C value of bulk paleosol organic matter | CA7: NA | CB7: NA | CC7: NA | CD7: NA | CE7: NA | CF7: NA | CG7: -5.1 | CH7: other | CI7: assuming 21‰ fractionation between d13Ca and d13Corg | CJ7: Mora et al., 1995 | CK7: NA | CL7: NA | CM7: NA | CN7: NA | CO7: 25 | CP7: other | CQ7: paleolatitude, maximum monthly temperature | CR7: Ekart et al., 1998 | CS7: NA | CT7: NA | CU7: NA | CV7: NA | CW7: NA | CX7: NA | CY7: NA | CZ7: NA | DA7: NA | DB7: NA | DC7: NA | DD7: NA | DE7: NA | DF7: NA | DG7: NA | DH7: NA | DI7: NA | DJ7: NA | DK7: NA | DL7: NA | DM7: 3000-5000 | DN7: NA | DO7: NA | DP7: NA | DQ7: NA | DR7: NA | DS7: NA | DT7: NA | DU7: aridisol | DV7: USDA | DW7: NA | DX7: NA | DY7: NA | DZ7: sand | EA7: nodules | EB7: NA | EC7: >25 | ED7: NA | EE7: NA | EF7: NA | EG7: NA | EH7: NA | EI7: NA | EJ7: NA | EK7: B | EL7: NA | EM7: NA | EN7: NA | EO7: NA | EP7: NA | EQ7: NA | ER7: NA | ES7: NA | ET7: NA | EU7: NA | EV7: NA | EW7: 2225 | EX7: NA | EY7: 550 | EZ7: 550 | FA7: S(z) | FB7: NA | FC7: NA | FD7: NA | FE7: NA | FF7: NA
A8: paleosol | B8: ='Start here when entering data'!$D$11 -> Ghosh | C8: ='Start here when entering data'!$D$12 -> 2005 | D8: ='Start here when entering data'!$D$13 -> 10.1007/0-387-27048-5_2 | E8: =IF( Z8="NA","NA",Z8*1000) -> 80000 | F8: =IF( AA8="NA","NA",AA8*1000) -> 15000 | G8: =IF( AB8="NA","NA",AB8*1000) -> 15000 | H8: =IF(EX8="NA",EW8,EX8) -> 1480 | I8: =IF( EY8="NA","NA",EY8) -> 370 | J8: =IF( EZ8="NA","NA",EZ8) -> 370 | K8: ='Start here when entering data'!$D$8 -> Jiawei Da | L8: ='Start here when entering data'!$D$9 -> jiawei@utexas.edu | M8: ='Start here when entering data'!$D$14 -> Ghosh P, Bhattacharya S K, Ghosh P. Atmospheric CO2 during the Late Paleozoic and Mesozoic: estimates from Indian soils[M]//A history of atmospheric CO2 and its effects on plants, animals, and ecosystems. New York, NY: Springer New York, 2005: 8-34. | N8: Ghosh P, Bhattacharya S K, Jani R A. Palaeoclimate and palaeovegetation in central India during the Upper Cretaceous based on stable isotope composition of the palaeosol carbonates[J]. Palaeogeography, Palaeoclimatology, Palaeoecology, 1995, 114(2-4): 285-296. | O8: Ghosh et al (1995) provided the isotopic data for Lameta formation | P8: NA | Q8: Lameta | R8: NA | S8: NA | T8: NA | U8: NA | V8: NA | W8: NA | X8: NA | Y8: NA | Z8: 80 | AA8: 15 | AB8: 15 | AC8: NA | AD8: NA | AE8: NA | AF8: NA | AG8: -9.1 | AH8: 2 | AI8: 19 | AJ8: Ghosh P, Bhattacharya S K, Jani R A. Palaeoclimate and palaeovegetation in central India during the Upper Cretaceous based on stable isotope composition of the palaeosol carbonates[J]. Palaeogeography, Palaeoclimatology, Palaeoecology, 1995, 114(2-4): 285-296. | AK8: -27.3 | AL8: NA | AM8: 1 | AN8: NA | AO8: NA | AP8: NA | AQ8: Ghosh P, Bhattacharya S K, Jani R A. Palaeoclimate and palaeovegetation in central India during the Upper Cretaceous based on stable isotope composition of the palaeosol carbonates[J]. Palaeogeography, Palaeoclimatology, Palaeoecology, 1995, 114(2-4): 285-296. | AR8: NA | AS8: NA | AT8: NA | AU8: NA | AV8: -8 | AW8: 2 | AX8: 19 | AY8: Ghosh P, Bhattacharya S K, Jani R A. Palaeoclimate and palaeovegetation in central India during the Upper Cretaceous based on stable isotope composition of the palaeosol carbonates[J]. Palaeogeography, Palaeoclimatology, Palaeoecology, 1995, 114(2-4): 285-296. | AZ8: NA | BA8: NA | BB8: NA | BC8: NA | BD8: NA | BE8: NA | BF8: NA | BG8: NA | BH8: NA | BI8: NA | BJ8: NA | BK8: NA | BL8: NA | BM8: NA | BN8: NA | BO8: NA | BP8: NA | BQ8: NA | BR8: NA | BS8: NA | BT8: NA | BU8: NA | BV8: NA | BW8: NA | BX8: NA | BY8: -27.6 | BZ8: equal to d13C value of bulk paleosol organic matter | CA8: NA | CB8: NA | CC8: NA | CD8: NA | CE8: NA | CF8: NA | CG8: -6.6 | CH8: other | CI8: assuming 21‰ fractionation between d13Ca and d13Corg | CJ8: Mora et al., 1996 | CK8: NA | CL8: NA | CM8: NA | CN8: NA | CO8: 25 | CP8: other | CQ8: paleolatitude, maximum monthly temperature | CR8: Ekart et al., 1999 | CS8: NA | CT8: NA | CU8: NA | CV8: NA | CW8: NA | CX8: NA | CY8: NA | CZ8: NA | DA8: NA | DB8: NA | DC8: NA | DD8: NA | DE8: NA | DF8: NA | DG8: NA | DH8: NA | DI8: NA | DJ8: NA | DK8: NA | DL8: NA | DM8: 3000-5000 | DN8: NA | DO8: NA | DP8: NA | DQ8: NA | DR8: NA | DS8: NA | DT8: NA | DU8: aridisol | DV8: USDA | DW8: NA | DX8: NA | DY8: NA | DZ8: sand | EA8: nodules | EB8: NA | EC8: >25 | ED8: NA | EE8: NA | EF8: NA | EG8: NA | EH8: NA | EI8: NA | EJ8: NA | EK8: B | EL8: NA | EM8: NA | EN8: NA | EO8: NA | EP8: NA | EQ8: NA | ER8: NA | ES8: NA | ET8: NA | EU8: NA | EV8: NA | EW8: 1480 | EX8: NA | EY8: 370 | EZ8: 370 | FA8: S(z) | FB8: NA | FC8: NA | FD8: NA | FE8: NA | FF8: NA

Sheet age data
A1: On this sheet, each row corresponds to a unique stratgraphic depth at which the age has been estimated
A2: Age-depth data | F2: Stratigraphic ages | S2: Radiometric ages
F3: Magnetostratigraphy | J3: Biostratigraphy | L3: Chemostratigraphy | P3: Relevant for all stratigraphic ages
C4: pull down menu with following options: <,<=, =, >=, >. | S4: pull down menu with following options: Volcanic ash, lava, volcaniclastic deposit, sedimentary deposit, authigenic deposit | U4: pull down menu with following options: sanidine, zircon, biotite, apatite, carbonate, other | W4: pull down menu with following options: K-Ar, Ar-Ar, U-Pb, fission track, 14C, U-series, other | Z4: pull down menu with LA ICPMS, solution mode ICPMS, TIMS, SIMS, AMS, etc. | AD4: Pull down menu with the following options: youngest single grain, youngest graphical peak, youngest grain cluster at 1s, youngest grain cluster at 2s, youngest detrital zircon, TuffZirc 6+ (Tucker et al., 2013), youngest three zircons, t method (Barbeau et al., 2009), other, NA
A5: If CO2 estimates reported in the study come from more than one section (sedimentary sequence), this column should be used to disambigute sections. This is especially useful for linking data on this tab with the appropriate rows on the paleosol data tab. | B5: The height above or depth below a recognizable boundary or interval. Organize data from youngest at the top to oldest at the bottom. The data entered on this tab will be used to generate an age model for the CO2 estimates on the paleosol data tab. Therefore, the values entered in this coulmn should be directly comparable with those ented in the stratigraphic level column on paleosol data tab. The stratigraphic levels here may (in most cases will) fall between the stratigraphic levels at which materials used to estimate paleoatmospheric CO2 occur. | C5: Use the pull-down menu to selet the appropriate type of age constraint at each stratigraphic level. For instance, DZ ages would be entered as <=, the age of the top of a section could be entered as >= if a biozone is known but a boundary is not exposed, and the age of the bottom of a section that lies nonconformably on plutonic rocks could be entered as <= the age of the pluton. | F5: enter chron or chron boundary name if it provides unique information with which to construct an age-depth model, otherwise enter NA | G5: if applicable, enter the publication in which the magnetostratigraphy was reported | H5: What independent age information was used to determine which chrons the observed polarity reversals might align with? | J5: enter biozone or biozone boundary name if it provides unique information with which to construct an age-depth model, otherwise enter NA | K5: if applicable, enter the publication in which the biostratigraphy was reported | P5: the exact positions of boundaries are not known. This column allows entry of the lowest stratigraphic level at which a boundary could occur | Q5: the exact positions of boundaries are not known. This column allows entry of the highest stratigraphic level at which a boundary could occur | R5: Enter the version of the geologic timescale (or other reference) used to evalaute the numerical age based on bio-, chemo- or magnetostratigraphic data | S5: Select from pull-down menu | T5: if other is selected in previous column, enter name of other type of deposit. Otherwise enter NA | U5: Select from pull-down menu | V5: if other is selected in previous column, enter name of other mineral. Otherwise enter NA | W5: Select from pull-down menu | X5: if other is selected in previous column, enter name of other radiogenic system. Otherwise enter NA | Y5: enter the value of the deacy constant used to caluclate an age | Z5: Select from pull-down menu | AA5: if other is selected in previous column, enter name of other analytical method. Otherwise enter NA | AB5: if applicable, enter the publication in which the radiometric age was reported | AC5: for detrital zircon | AD5: Select from pull-down menu | AE5: if other is selected in previous column, enter name of other type of maximum deposiitonal DZ age here. Otherwise enter NA | AF5: List any additional details that might be important at specific stratigraphic levels. For general notes about the age-depth model, use the 'notes on age determination' column in the paleosol data tab.
A6: section number | B6: Stratigraphic level (m) | C6: type of age constraint | D6: age (Ma) | E6: age uncertainty (±2s) | F6: chron or chron boundary | G6: reference for magnetostratigraphy | H6: independent evidence for comparison to geomagnetic timescale | I6: reference for evidence | J6: biozone or biozone boundary name | K6: reference for bioostratigraphy | L6: C isotope segment or segment boundary name (example: C1, C2, Ap1, Ap2, C1-C2,Ap1-Ap2, etc.) | M6: Reference for C-isotope nomenclature | N6: reference for carbon isotope data used to infer C-isotope segments | O6: Name of C-cycle perturbation (e.g., Toarcian OAE, Selli Event, etc. ) | P6: bottom stratigraphic level for boundary | Q6: top stratigraphic level for boundary | R6: Geologic timescale used | S6: type of deposit for radiometric age | T6: other type of deposit | U6: mineral for radiometric age | V6: other mineral | W6: radiogenic system for radiometric age | X6: other radiogenic system | Y6: decay constant assumed | Z6: analytical method | AA6: other analytical method | AB6: reference for radiometric age | AC6: number of grains analyzed | AD6: type of maximum depositional DZ age | AE6: other type of maximum depositional DZ age | AF6: Notes

Sheet Start here when entering data
A3: The questions and prompts on this tab will facilitate data entry on the 'paleosol data' tab
A5: Step 1: Please fill out the following questions about you and the data source
A7: Information about you | D7: *REQUIRED*
C8: Name of person entering data into this sheet | D8: Jiawei Da
C9: Email address of person entering data into this sheet | D9: jiawei@utexas.edu
A10: Information about study this data is from
C11: Last name of first author of the study from which you are entering data (in most cases, this is the study that reported paleoCO2) | D11: Ghosh
C12: Publication year of the study from which you are entering | D12: 2005
C13: DOI of the study from which you are entering | D13: 10.1007/0-387-27048-5_2
C14: The full reference of the study from you are entering | D14: Ghosh P, Bhattacharya S K, Ghosh P. Atmospheric CO2 during the Late Paleozoic and Mesozoic: estimates from Indian soils[M]//A history of atmospheric CO2 and its effects on plants, animals, and ecosystems. New York, NY: Springer New York, 2005: 8-34.
A17: Step 2: Please select the appropriate answer from the pulldown menus for each of the folliwing questions. Entering ‘no’ in response to the following questions will color the text grey in some columns on the 'paleosol data' tab but these columns will remain accessible.
D18: *REQUIRED*
C19: Are bulk geochemistry measurements part of this dataset? | D19: no
C20: Are measurements of the d13C values of occluded organic matter part of this dataset? | D20: yes
C21: Are measurements of the d13C values of bulk organic matter part of this dataset? | D21: no
C22: Are measurements of the d13C values of tooth enamel part of this dataset? | D22: no
C23: Are measurements of the d18O values of paleosol carbonates part of this dataset? | D23: yes
C24: Are clumped isotope – derived temperatures part of this dataset? | D24: no
A26: Step 3: Please fill the paleosol and age data tabs
C27: Please follow instructions at the top of the 'paleosol data' and 'age data' tabs. We have pre-populated 100 rows in each sheet with equations and pull down menus to help you populate values. In the paleosol data sheet, we have also pre-propulated cells that were not autofilled in step 2 with NAs (in red text). Please replace NA where appropriate and leave NA where appropriate (for the study you are entering). Turn the text color black to keep track of your work and distinguish pre-polulated NA (red) from user-specified NA (black).
A28: Step 4: Before submitting, please enter the total number of rows you populated in the paleosol data sheet
D29: *REQUIRED*
C30: How many rows did you use? One row will be used for every carbonate nodule (or other carbonate type), tooth, or bulk paleosol sample. | D30: 5

Sheet vocabs
B1: Paleosol Data Tab | D1: Paleosol Data Tab | F1: Age Data Tab | H1: Start Tab
A2: T | B2: Pull down menu with following options: NAD 83, WGS 84, ITRF, GRS 80, other, NA | C2: DV | D2: Pull down menu with following options: USDA, FAO, Russian Soil Classification System, Australian Soil Classification, Canadian System of Soil Slassification, French Soil Reference System, WRB, other, NA | E2: C | F2: pull down menu with following options: <,<=, =, >=, >. Use the pull-down menu to selet the appropriate type of age constraint at each stratigraphic level. For instance, DZ ages would be entered as <=, the age of the top of a section could be entered as >= if a biozone is known but a boundary is not exposed, and the age of the bottom of a section that lies nonconformably on plutonic rocks could be entered as <= the age of the pluton. | H2: Boolean
B3: NAD 83 | D3: USDA | F3: < | H3: yes
B4: WGS 84 | D4: FAO | F4: <= | H4: no
B5: ITRF | D5: Russian Soil Classification System | F5: =
B6: GRS 80 | D6: Australian Soil Classification | F6: >=
B7: other | D7: Canadian System of Soil Slassification | F7: >
B8: NA | D8: French Soil Reference System
D9: WRB
D10: other
D11: NA
A15: BZ
B16: from d13Ca, from d13C value of coal (e.g., following Arens et al., 2000), equal to d13C value of bulk paleosol organic matter, equal to d13C value of organic matter occluded in paleosol calcium carbonate, from d13C value of bulk paleosol organic matter plus/minus adjustment term, from d13C value of organic matter occluded in paleosol calcium carbonate plus/minus adjustment term, other, NA) | C16: DZ | D16: Pull down menu with following options: gravel, sand, mud, NA. The predominant grain size in the paleosol if measured | E16: S | F16: pull down menu with following options: Volcanic ash, lava, volcaniclastic deposit, sedimentary deposit, authigenic deposit
B17: from d13Ca | D17: gravel | F17: Volcanic ash
B18: from d13C value of coal (e.g. following Arens et al., 2000) | D18: sand | F18: lava
B19: equal to d13C value of bulk paleosol organic matter | D19: mud | F19: volcaniclastic deposit
B20: equal to d13C value of organic matter occluded in paleosol calcium carbonate | D20: NA | F20: sedimentary deposit
B21: from d13C value of bulk paleosol organic matter plus/minus adjustment term | F21: authigenic deposit
B22: from d13C value of organic matter occluded in paleosol calcium carbonate plus/minus adjustment term
B23: other
B24: NA
C25: EA | D25: Pull down menu with following options: nodules, rhizoliths, filaments, clast coatings, disseminated carbonate, other, NA
D26: nodules
D27: rhizoliths
D28: filaments
A29: CH | D29: clast coatings
B30: from d13C values of coal (e.g., following Arens et al., 2000), from d13C values of marine carbonates (e.g., following Passey et al 2002 or Tipple et al., 2010), other, NA | D30: disseminated carbonate | E30: U | F30: pull down menu with following options: sanidine, zircon, biotite, apatite, carbonate, other
B31: from d13C value of coal (e.g. following Arens et al., 2000) | D31: other | F31: sanidine
B32: from d13C values of marine carbonates (e.g. following Passey et al 2002 or Tipple et al. 2010 | D32: NA | F32: zircon
B33: other | F33: biotite
B34: NA | F34: apatite
F35: carbonate
C36: EE | D36: Pull down menu with following options: TL, CL, TL + CL, other, NA. TL = transmitted light, CL= cathodoluminescence | F36: other
D37: TL
A38: CP | D38: CL
B39: clumped isotope themometry, paleosol carbonate d18O (e.g., following Dworkin et al. 2005) , paleosol salinization (e.g., following Sheldon et al., 2002), paleosol weathering index (e.g., following Gallagher and Sheldon 2013), ppm1.0 (following Stinchcomb et al., 2016), other, NA | D39: TL + CL | E39: W | F39: pull down menu with following options: K-Ar, Ar-Ar, U-Pb, fission track, 14C, U-series, other
B40: clumped isotope themometry | D40: other | F40: K-Ar
B41: paleosol carbonate d18O (e.g. following Dworkin et al. 2005) | D41: NA | F41: Ar-Ar
B42: paleosol salinization (e.g. following Sheldon et al. 2002) | F42: U-Pb
B43: paleosol weathering index (e.g. following Gallagher and Sheldon 2013) | F43: fission track
...
